<?xml version="1.0"?>
<robot name="Space Jockey">
  <material name="blue"><color rgba=".2 .2 1 1"/></material>
  <material name="green"><color rgba=".1 .8 .1 1"/></material>
  <material name="silver"><color rgba=".7 .7 .7 1"/></material>
  <material name="red"><color rgba=".8 .1 .1 1"/></material>

  <link name="center_seg">
    <visual>
      <geometry>
        <box size=".095 .075 .032"/>
      </geometry>
      <origin xyz="0.0475 0 0"/>
      <material name="blue" />
    </visual>
  </link>

  <link name="center_aft">
    <visual>
      <geometry>
        <box size=".095 .075 .05"/>
      </geometry>
      <origin xyz="-0.0475 0 0"/>
      <material name="blue" />
    </visual>
  </link>

  <link name="fore_base_pole">
    <visual>
      <geometry>
        <box size=".162 .100 .032"/>
      </geometry>
      <origin xyz="0.081 0 0"/>
      <material name="green" />
    </visual>
  </link>

  <link name="fore_base_prism">
    <visual>
      <geometry>
        <cylinder length="0.15" radius=".010"/>
      </geometry>
      <origin rpy="0 1.57075 0 " xyz="-0.075 0 0"/>
      <material name="silver" />
    </visual>
  </link>

  <link name="front_seg">
    <visual>
      <geometry>
        <box size=".060 .095 .060"/>
      </geometry> 
      <origin xyz="0.030 0 -0.01763"/>
      <material name="blue" />
    </visual>
  </link>

  <link name="aft_base_pole">
    <visual>
      <geometry>
      	<box size=".162 .100 .032"/>
      </geometry>
      <origin xyz="-0.081 0 0"/>
      <material name="red" />
    </visual>
  </link>

  <link name="aft_base_prism">
    <visual>
      <geometry>
        <cylinder length="0.15" radius=".010"/>
      </geometry>
      <origin rpy="0 1.57075 0 " xyz="0.075 0 0"/>
      <material name="silver" />
    </visual>
  </link>

  <link name="rear_seg">
    <visual>
      <geometry>
        <box size=".060 .095 .060"/>
      </geometry> 
      <origin xyz="-0.030 0 -0.01763"/>
      <material name="blue"/>
    </visual>
  </link>

  <!--  stub frames  -->
  <link name="robot" />
  <link name="camera" />
  <link name="front_foot" />
  <link name="center_foot" />
  <link name="rear_foot" />

  <!-- this is a fake joint for communicating robot rotations from the IK easily -->
  <joint name="robot_rot" type="continuous"> 
    <axis xyz="0 0 1"/>
    <parent link="robot"/>
    <child link="center_aft"/>
    <origin xyz="0 0 .067" />
    <limit effort="1000.0" lower="-3.15" upper="3.15" velocity="2.094"/>
  </joint>

  <joint name="center_swivel" type="revolute">
    <axis xyz="0 0 1"/>
    <limit effort="1000.0" lower="-.35" upper=".35" velocity="2.094"/>
    <parent link="center_aft"/>
    <child link="center_seg"/>
  </joint>

  <joint name="fore_base_pitch" type="revolute">
    <axis xyz="0 1 0"/>
    <limit effort="1000.0" lower="-.6" upper=".6" velocity="2.094"/>
    <origin xyz="0.06985 0 0"/>
    <parent link="center_seg"/>
    <child link="fore_base_pole"/>
  </joint>

  <joint name="fore_extend" type="prismatic">
    <parent link="fore_base_pole"/>
    <child link="fore_base_prism"/>
    <limit effort="1000.0" lower="0.1902" upper="0.2781" velocity="0.048"/>
  </joint>

  <joint name="front_pitch" type="revolute">
    <axis xyz="0 1 0"/>
    <limit effort="1000.0" lower="-.52" upper=".78" velocity="2.094"/>
    <parent link="fore_base_prism"/>
    <child link="front_seg"/>
  </joint>

  <joint name="aft_base_pitch" type="revolute">
    <axis xyz="0 1 0"/>
    <limit effort="1000.0" lower="-.6" upper=".6" velocity="2.094"/>
    <origin xyz="-0.06985 0 0"/>
    <parent link="center_aft"/>
    <child link="aft_base_pole"/>
  </joint>

  <joint name="aft_extend" type="prismatic">
    <parent link="aft_base_pole"/>
    <child link="aft_base_prism"/>
    <axis xyz="-1 0 0"/>
    <limit effort="1000.0" lower="0.1902" upper="0.2781" velocity="0.048"/>
  </joint>

  <joint name="rear_pitch" type="revolute">
    <axis xyz="0 1 0"/>
    <limit effort="1000.0" lower="-.6" upper=".6" velocity="2.094"/>
    <parent link="aft_base_prism"/>
    <child link="rear_seg"/>
  </joint>

  <joint name="front_attach" type="fixed">
    <parent link="front_seg"/>
    <child link="front_foot"/>
    <!-- <limit effort="1000.0" lower="0" upper="0.006" velocity=" 2.094"/>
    <axis xyz="0 0 -1"/> -->
    <origin xyz="0.00069 0 -0.04763"/>
  </joint>

  <joint name="center_attach" type="prismatic">
    <parent link="robot"/>
    <child link="center_foot"/>
    <limit effort="1000.0" lower="0" upper="0.006" velocity="1.0"/>
    <axis xyz="0 0 -1"/>
  </joint>

  <joint name="rear_attach" type="fixed">
    <parent link="rear_seg"/>
    <child link="rear_foot"/>
    <!-- <limit effort="1000.0" lower="0" upper="0.006" velocity="0.5"/>
    <axis xyz="0 0 -1"/> -->
    <origin xyz="0.00069 0 -0.04763"/>
  </joint>

  <joint name="camera_fixed" type="fixed">
    <origin xyz=".082 .019 -.009" rpy="0 2.3562 0"/>
    <parent link="front_seg"/>
    <child link="camera"/>
  </joint>
</robot>

